Exception ignored in: <module 'threading' from '/usr/lib/python3.9/threading.py'>
Traceback (most recent call last):
  File "/usr/lib/python3.9/threading.py", line 1428, in _shutdown
    lock.acquire()
KeyboardInterrupt: 
function(*self.args, **self.kwargs)
  File "/home/vboxuser/Git/imt4905/rtun-routing/lsr.py", line 616, in shortest_paths
    shortest_paths = nx.shortest_path(G, global_router['RID'], weight='weight')
  File "/usr/local/lib/python3.9/dist-packages/networkx/classes/backends.py", line 145, in wrapper
    return func(*args, **kwds)
  File "/usr/local/lib/python3.9/dist-packages/networkx/algorithms/shortest_paths/generic.py", line 161, in shortest_path
    paths = nx.single_source_dijkstra_path(G, source, weight=weight)
  File "/usr/local/lib/python3.9/dist-packages/networkx/algorithms/shortest_paths/weighted.py", line 302, in single_source_dijkstra_path
    return multi_source_dijkstra_path(G, {source}, cutoff=cutoff, weight=weight)
  File "/usr/local/lib/python3.9/dist-packages/networkx/algorithms/shortest_paths/weighted.py", line 546, in multi_source_dijkstra_path
    length, path = multi_source_dijkstra(G, sources, cutoff=cutoff, weight=weight)
  File "/usr/local/lib/python3.9/dist-packages/networkx/algorithms/shortest_paths/weighted.py", line 734, in multi_source_dijkstra
    raise nx.NodeNotFound(f"Node {s} not found in graph")
networkx.exception.NodeNotFound: Node P3 not found in graph
Exception ignored in: <module 'threading' from '/usr/lib/python3.9/threading.py'>
Traceback (most recent call last):
  File "/usr/lib/python3.9/threading.py", line 1428, in _shutdown
    lock.acquire()
KeyboardInterrupt: 
