++ dirname ./startserver.sh
+ BASEDIR=.
+ SCRIPTPATH=./../../rtun-routing
+ export PYTHONPATH=./../../torpy-rtun-fork/
+ PYTHONPATH=./../../torpy-rtun-fork/
+ python3 ./../../rtun-routing/rtun.py -v INFO -g staysafeandgoodluck -f rendezvous.txt -t peer1peer2 -n default -i 4 -d 5
Exception in thread Thread-108:
Traceback (most recent call last):
  File "/usr/lib/python3.9/threading.py", line 954, in _bootstrap_inner
    self.run()
  File "/usr/lib/python3.9/threading.py", line 1266, in run
    self.function(*self.args, **self.kwargs)
  File "/home/vboxuser/Git/imt4905/rtun-routing/lsr.py", line 679, in runDijkstra
    rp_node = rp_paths[prev_node][next_node]
KeyError: 'P2'
Exception in thread Thread-273:
Traceback (most recent call last):
  File "/usr/lib/python3.9/threading.py", line 954, in _bootstrap_inner
    self.run()
  File "/usr/lib/python3.9/threading.py", line 1266, in run
    self.function(*self.args, **self.kwargs)
  File "/home/vboxuser/Git/imt4905/rtun-routing/lsr.py", line 679, in runDijkstra
    rp_node = rp_paths[prev_node][next_node]
KeyError: 'P2'
Exception in thread Thread-1221:
Traceback (most recent call last):
  File "/usr/lib/python3.9/threading.py", line 954, in _bootstrap_inner
    self.run()
  File "/usr/lib/python3.9/threading.py", line 1266, in run
    self.function(*self.args, **self.kwargs)
  File "/home/vboxuser/Git/imt4905/rtun-routing/lsr.py", line 679, in runDijkstra
    rp_node = rp_paths[prev_node][next_node]
KeyError: 'P3'
Exception in thread Thread-1225:
Traceback (most recent call last):
  File "/usr/lib/python3.9/threading.py", line 954, in _bootstrap_inner
    self.run()
  File "/usr/lib/python3.9/threading.py", line 1266, in run
    self.function(*self.args, **self.kwargs)
  File "/home/vboxuser/Git/imt4905/rtun-routing/lsr.py", line 679, in runDijkstra
    rp_node = rp_paths[prev_node][next_node]
KeyError: 'P3'
Exception in thread Thread-1234:
Traceback (most recent call last):
  File "/usr/lib/python3.9/threading.py", line 954, in _bootstrap_inner
    self.run()
  File "/usr/lib/python3.9/threading.py", line 1266, in run
    self.function(*self.args, **self.kwargs)
  File "/home/vboxuser/Git/imt4905/rtun-routing/lsr.py", line 679, in runDijkstra
    rp_node = rp_paths[prev_node][next_node]
KeyError: 'P3'
Exception in thread Thread-1241:
Traceback (most recent call last):
  File "/usr/lib/python3.9/threading.py", line 954, in _bootstrap_inner
    self.run()
  File "/usr/lib/python3.9/threading.py", line 1266, in run
    self.function(*self.args, **self.kwargs)
  File "/home/vboxuser/Git/imt4905/rtun-routing/lsr.py", line 679, in runDijkstra
    rp_node = rp_paths[prev_node][next_node]
KeyError: 'P3'
Exception in thread Thread-1253:
Traceback (most recent call last):
  File "/usr/lib/python3.9/threading.py", line 954, in _bootstrap_inner
    self.run()
  File "/usr/lib/python3.9/threading.py", line 1266, in run
    self.function(*self.args, **self.kwargs)
  File "/home/vboxuser/Git/imt4905/rtun-routing/lsr.py", line 679, in runDijkstra
    rp_node = rp_paths[prev_node][next_node]
KeyError: 'P3'
Exception in thread Thread-1254:
Traceback (most recent call last):
  File "/usr/lib/python3.9/threading.py", line 954, in _bootstrap_inner
    self.run()
  File "/usr/lib/python3.9/threading.py", line 1266, in run
    self.function(*self.args, **self.kwargs)
  File "/home/vboxuser/Git/imt4905/rtun-routing/lsr.py", line 679, in runDijkstra
    rp_node = rp_paths[prev_node][next_node]
KeyError: 'P3'
Exception in thread Thread-1269:
Traceback (most recent call last):
  File "/usr/lib/python3.9/threading.py", line 954, in _bootstrap_inner
    self.run()
  File "/usr/lib/python3.9/threading.py", line 1266, in run
    self.function(*self.args, **self.kwargs)
  File "/home/vboxuser/Git/imt4905/rtun-routing/lsr.py", line 679, in runDijkstra
    rp_node = rp_paths[prev_node][next_node]
KeyError: 'P3'
Exception in thread Thread-1276:
Traceback (most recent call last):
  File "/usr/lib/python3.9/threading.py", line 954, in _bootstrap_inner
    self.run()
  File "/usr/lib/python3.9/threading.py", line 1266, in run
    self.function(*self.args, **self.kwargs)
  File "/home/vboxuser/Git/imt4905/rtun-routing/lsr.py", line 679, in runDijkstra
    rp_node = rp_paths[prev_node][next_node]
KeyError: 'P3'
Exception in thread Thread-1285:
Traceback (most recent call last):
  File "/usr/lib/python3.9/threading.py", line 954, in _bootstrap_inner
    self.run()
  File "/usr/lib/python3.9/threading.py", line 1266, in run
    self.function(*self.args, **self.kwargs)
  File "/home/vboxuser/Git/imt4905/rtun-routing/lsr.py", line 679, in runDijkstra
    rp_node = rp_paths[prev_node][next_node]
KeyError: 'P3'
Exception in thread Thread-1289:
Traceback (most recent call last):
  File "/usr/lib/python3.9/threading.py", line 954, in _bootstrap_inner
    self.run()
  File "/usr/lib/python3.9/threading.py", line 1266, in run
    self.function(*self.args, **self.kwargs)
  File "/home/vboxuser/Git/imt4905/rtun-routing/lsr.py", line 679, in runDijkstra
    rp_node = rp_paths[prev_node][next_node]
KeyError: 'P3'
Exception in thread Thread-1313:
Traceback (most recent call last):
  File "/usr/lib/python3.9/threading.py", line 954, in _bootstrap_inner
    self.run()
  File "/usr/lib/python3.9/threading.py", line 1266, in run
    self.function(*self.args, **self.kwargs)
  File "/home/vboxuser/Git/imt4905/rtun-routing/lsr.py", line 679, in runDijkstra
    rp_node = rp_paths[prev_node][next_node]
KeyError: 'P3'
Exception in thread Thread-1317:
Traceback (most recent call last):
  File "/usr/lib/python3.9/threading.py", line 954, in _bootstrap_inner
    self.run()
  File "/usr/lib/python3.9/threading.py", line 1266, in run
    self.function(*self.args, **self.kwargs)
  File "/home/vboxuser/Git/imt4905/rtun-routing/lsr.py", line 679, in runDijkstra
    rp_node = rp_paths[prev_node][next_node]
KeyError: 'P3'
Exception in thread Thread-1329:
Traceback (most recent call last):
  File "/usr/lib/python3.9/threading.py", line 954, in _bootstrap_inner
    self.run()
  File "/usr/lib/python3.9/threading.py", line 1266, in run
    self.function(*self.args, **self.kwargs)
  File "/home/vboxuser/Git/imt4905/rtun-routing/lsr.py", line 679, in runDijkstra
    rp_node = rp_paths[prev_node][next_node]
KeyError: 'P3'
Exception in thread Thread-1333:
Traceback (most recent call last):
  File "/usr/lib/python3.9/threading.py", line 954, in _bootstrap_inner
    self.run()
  File "/usr/lib/python3.9/threading.py", line 1266, in run
    self.function(*self.args, **self.kwargs)
  File "/home/vboxuser/Git/imt4905/rtun-routing/lsr.py", line 679, in runDijkstra
    rp_node = rp_paths[prev_node][next_node]
KeyError: 'P3'
Exception in thread Thread-1348:
Traceback (most recent call last):
  File "/usr/lib/python3.9/threading.py", line 954, in _bootstrap_inner
    self.run()
  File "/usr/lib/python3.9/threading.py", line 1266, in run
    self.function(*self.args, **self.kwargs)
  File "/home/vboxuser/Git/imt4905/rtun-routing/lsr.py", line 679, in runDijkstra
    rp_node = rp_paths[prev_node][next_node]
KeyError: 'P3'
Exception in thread Thread-1352:
Traceback (most recent call last):
  File "/usr/lib/python3.9/threading.py", line 954, in _bootstrap_inner
    self.run()
  File "/usr/lib/python3.9/threading.py", line 1266, in run
    self.function(*self.args, **self.kwargs)
  File "/home/vboxuser/Git/imt4905/rtun-routing/lsr.py", line 679, in runDijkstra
    rp_node = rp_paths[prev_node][next_node]
KeyError: 'P3'
Exception in thread Thread-1364:
Traceback (most recent call last):
  File "/usr/lib/python3.9/threading.py", line 954, in _bootstrap_inner
    self.run()
  File "/usr/lib/python3.9/threading.py", line 1266, in run
    self.function(*self.args, **self.kwargs)
  File "/home/vboxuser/Git/imt4905/rtun-routing/lsr.py", line 679, in runDijkstra
    rp_node = rp_paths[prev_node][next_node]
KeyError: 'P3'
Exception in thread Thread-1368:
Traceback (most recent call last):
  File "/usr/lib/python3.9/threading.py", line 954, in _bootstrap_inner
    self.run()
  File "/usr/lib/python3.9/threading.py", line 1266, in run
    self.function(*self.args, **self.kwargs)
  File "/home/vboxuser/Git/imt4905/rtun-routing/lsr.py", line 679, in runDijkstra
    rp_node = rp_paths[prev_node][next_node]
KeyError: 'P3'
Exception in thread Thread-1377:
Traceback (most recent call last):
  File "/usr/lib/python3.9/threading.py", line 954, in _bootstrap_inner
    self.run()
  File "/usr/lib/python3.9/threading.py", line 1266, in run
    self.function(*self.args, **self.kwargs)
  File "/home/vboxuser/Git/imt4905/rtun-routing/lsr.py", line 679, in runDijkstra
    rp_node = rp_paths[prev_node][next_node]
KeyError: 'P3'
Exception in thread Thread-1384:
Traceback (most recent call last):
  File "/usr/lib/python3.9/threading.py", line 954, in _bootstrap_inner
    self.run()
  File "/usr/lib/python3.9/threading.py", line 1266, in run
    self.function(*self.args, **self.kwargs)
  File "/home/vboxuser/Git/imt4905/rtun-routing/lsr.py", line 679, in runDijkstra
    rp_node = rp_paths[prev_node][next_node]
KeyError: 'P3'
Exception in thread Thread-1399:
Traceback (most recent call last):
  File "/usr/lib/python3.9/threading.py", line 954, in _bootstrap_inner
    self.run()
  File "/usr/lib/python3.9/threading.py", line 1266, in run
    self.function(*self.args, **self.kwargs)
  File "/home/vboxuser/Git/imt4905/rtun-routing/lsr.py", line 679, in runDijkstra
    rp_node = rp_paths[prev_node][next_node]
KeyError: 'P3'
Exception in thread Thread-1403:
Traceback (most recent call last):
  File "/usr/lib/python3.9/threading.py", line 954, in _bootstrap_inner
    self.run()
  File "/usr/lib/python3.9/threading.py", line 1266, in run
    self.function(*self.args, **self.kwargs)
  File "/home/vboxuser/Git/imt4905/rtun-routing/lsr.py", line 679, in runDijkstra
    rp_node = rp_paths[prev_node][next_node]
KeyError: 'P3'
Exception in thread Thread-1411:
Traceback (most recent call last):
  File "/usr/lib/python3.9/threading.py", line 954, in _bootstrap_inner
    self.run()
  File "/usr/lib/python3.9/threading.py", line 1266, in run
    self.function(*self.args, **self.kwargs)
  File "/home/vboxuser/Git/imt4905/rtun-routing/lsr.py", line 679, in runDijkstra
    rp_node = rp_paths[prev_node][next_node]
KeyError: 'P3'
Exception in thread Thread-1429:
Traceback (most recent call last):
  File "/usr/lib/python3.9/threading.py", line 954, in _bootstrap_inner
    self.run()
  File "/usr/lib/python3.9/threading.py", line 1266, in run
    self.function(*self.args, **self.kwargs)
  File "/home/vboxuser/Git/imt4905/rtun-routing/lsr.py", line 679, in runDijkstra
    rp_node = rp_paths[prev_node][next_node]
KeyError: 'P3'
Exception in thread Thread-1433:
Traceback (most recent call last):
  File "/usr/lib/python3.9/threading.py", line 954, in _bootstrap_inner
    self.run()
  File "/usr/lib/python3.9/threading.py", line 1266, in run
    self.function(*self.args, **self.kwargs)
  File "/home/vboxuser/Git/imt4905/rtun-routing/lsr.py", line 679, in runDijkstra
    rp_node = rp_paths[prev_node][next_node]
KeyError: 'P3'
Exception in thread Thread-1445:
Traceback (most recent call last):
  File "/usr/lib/python3.9/threading.py", line 954, in _bootstrap_inner
    self.run()
  File "/usr/lib/python3.9/threading.py", line 1266, in run
    self.function(*self.args, **self.kwargs)
  File "/home/vboxuser/Git/imt4905/rtun-routing/lsr.py", line 679, in runDijkstra
    rp_node = rp_paths[prev_node][next_node]
KeyError: 'P3'
Exception in thread Thread-1450:
Traceback (most recent call last):
  File "/usr/lib/python3.9/threading.py", line 954, in _bootstrap_inner
    self.run()
  File "/usr/lib/python3.9/threading.py", line 1266, in run
    self.function(*self.args, **self.kwargs)
  File "/home/vboxuser/Git/imt4905/rtun-routing/lsr.py", line 679, in runDijkstra
    rp_node = rp_paths[prev_node][next_node]
KeyError: 'P3'
Exception in thread Thread-1458:
Traceback (most recent call last):
  File "/usr/lib/python3.9/threading.py", line 954, in _bootstrap_inner
    self.run()
  File "/usr/lib/python3.9/threading.py", line 1266, in run
    self.function(*self.args, **self.kwargs)
  File "/home/vboxuser/Git/imt4905/rtun-routing/lsr.py", line 679, in runDijkstra
    rp_node = rp_paths[prev_node][next_node]
KeyError: 'P3'
Exception in thread Thread-1463:
Traceback (most recent call last):
  File "/usr/lib/python3.9/threading.py", line 954, in _bootstrap_inner
    self.run()
  File "/usr/lib/python3.9/threading.py", line 1266, in run
    self.function(*self.args, **self.kwargs)
  File "/home/vboxuser/Git/imt4905/rtun-routing/lsr.py", line 679, in runDijkstra
    rp_node = rp_paths[prev_node][next_node]
KeyError: 'P3'
Exception in thread Thread-1470:
Traceback (most recent call last):
  File "/usr/lib/python3.9/threading.py", line 954, in _bootstrap_inner
    self.run()
  File "/usr/lib/python3.9/threading.py", line 1266, in run
    self.function(*self.args, **self.kwargs)
  File "/home/vboxuser/Git/imt4905/rtun-routing/lsr.py", line 679, in runDijkstra
    rp_node = rp_paths[prev_node][next_node]
KeyError: 'P3'
Exception in thread Thread-1485:
Traceback (most recent call last):
  File "/usr/lib/python3.9/threading.py", line 954, in _bootstrap_inner
    self.run()
  File "/usr/lib/python3.9/threading.py", line 1266, in run
    self.function(*self.args, **self.kwargs)
  File "/home/vboxuser/Git/imt4905/rtun-routing/lsr.py", line 679, in runDijkstra
    rp_node = rp_paths[prev_node][next_node]
KeyError: 'P3'
Exception in thread Thread-1492:
Traceback (most recent call last):
  File "/usr/lib/python3.9/threading.py", line 954, in _bootstrap_inner
    self.run()
  File "/usr/lib/python3.9/threading.py", line 1266, in run
    self.function(*self.args, **self.kwargs)
  File "/home/vboxuser/Git/imt4905/rtun-routing/lsr.py", line 679, in runDijkstra
    rp_node = rp_paths[prev_node][next_node]
KeyError: 'P3'
Exception in thread Thread-1507:
Traceback (most recent call last):
  File "/usr/lib/python3.9/threading.py", line 954, in _bootstrap_inner
Exception in thread Thread-1520:
Traceback (most recent call last):
  File "/usr/lib/python3.9/threading.py", line 954, in _bootstrap_inner
Exception in thread Thread-1527:
Traceback (most recent call last):
    self.run()
  File "/usr/lib/python3.9/threading.py", line 1266, in run
Exception in thread Thread-1515:
Traceback (most recent call last):
    self.function(*self.args, **self.kwargs)
  File "/home/vboxuser/Git/imt4905/rtun-routing/lsr.py", line 679, in runDijkstra
  File "/usr/lib/python3.9/threading.py", line 954, in _bootstrap_inner
Exception in thread Establish-Vulnerar:
  File "/usr/lib/python3.9/threading.py", line 954, in _bootstrap_inner
    rp_node = rp_paths[prev_node][next_node]
KeyError: 'P3'
    self.run()
    self.run()
    self.run()
Traceback (most recent call last):
  File "/usr/lib/python3.9/threading.py", line 1266, in run
  File "/usr/lib/python3.9/threading.py", line 1266, in run
    self.function(*self.args, **self.kwargs)
  File "/home/vboxuser/Git/imt4905/rtun-routing/lsr.py", line 679, in runDijkstra
  File "/usr/lib/python3.9/threading.py", line 1266, in run
  File "/usr/lib/python3.9/threading.py", line 954, in _bootstrap_inner
    rp_node = rp_paths[prev_node][next_node]
KeyError: 'P3'
    self.function(*self.args, **self.kwargs)
  File "/home/vboxuser/Git/imt4905/rtun-routing/lsr.py", line 679, in runDijkstra
    rp_node = rp_paths[prev_node][next_node]
KeyError: 'P3'
    self.function(*self.args, **self.kwargs)
  File "/home/vboxuser/Git/imt4905/rtun-routing/lsr.py", line 679, in runDijkstra
    rp_node = rp_paths[prev_node][next_node]
KeyError: 'P3'
    self.run()
  File "/home/vboxuser/Git/imt4905/rtun-routing/rendezvous.py", line 132, in run
    data = stream.recv(1024)
  File "/home/vboxuser/Git/imt4905/torpy-rtun-fork/torpy/stream.py", line 374, in recv
    raise Exception('recv timeout')
Exception: recv timeout
Exception ignored in: <module 'threading' from '/usr/lib/python3.9/threading.py'>
Traceback (most recent call last):
  File "/usr/lib/python3.9/threading.py", line 1428, in _shutdown
    lock.acquire()
KeyboardInterrupt: 
