++ dirname ./startserver.sh
+ BASEDIR=.
+ SCRIPTPATH=./../../rtun-routing
+ export PYTHONPATH=./../../torpy-rtun-fork/
+ PYTHONPATH=./../../torpy-rtun-fork/
+ python3 ./../../rtun-routing/rtun.py -v INFO -g staysafeandgoodluck -f rendezvous.txt -t peer1peer2 -n default -i 2 -d 1
Exception in thread Thread-4:
Traceback (most recent call last):
  File "/usr/lib/python3.9/threading.py", line 954, in _bootstrap_inner
    self.run()
  File "/usr/lib/python3.9/threading.py", line 1266, in run
    self.function(*self.args, **self.kwargs)
  File "/home/vboxuser/Git/imt4905/rtun-routing/lsr.py", line 478, in checkForNodeFailure
    self.remove_inactive()
  File "/home/vboxuser/Git/imt4905/rtun-routing/lsr.py", line 355, in remove_inactive
    remove_circuit(self.inactive_list)
  File "/home/vboxuser/Git/imt4905/rtun-routing/lsr.py", line 1000, in remove_circuit
    th = rnd.threads[tid]
KeyError: 139637708289792
Exception ignored in: <module 'threading' from '/usr/lib/python3.9/threading.py'>
Traceback (most recent call last):
  File "/usr/lib/python3.9/threading.py", line 1428, in _shutdown
    lock.acquire()
KeyboardInterrupt: 
