++ dirname ./startserver.sh
+ BASEDIR=.
+ SCRIPTPATH=./../../rtun-routing
+ export PYTHONPATH=./../../torpy-rtun-fork/
+ PYTHONPATH=./../../torpy-rtun-fork/
+ python3 ./../../rtun-routing/rtun.py -v ERROR -g NeelTorRelay2 -f rendezvous.txt -t peer1peer2 -n default -i 4 -d 5
Exception in thread Thread-326:
Traceback (most recent call last):
  File "/usr/lib/python3.9/threading.py", line 954, in _bootstrap_inner
    self.run()
  File "/usr/lib/python3.9/threading.py", line 1266, in run
    self.function(*self.args, **self.kwargs)
  File "/home/vboxuser/Git/imt4905/rtun-routing/lsr.py", line 662, in runDijkstra
    rp_node = rp_paths[prev_node][next_node]
KeyError: 'P1'
Exception in thread Thread-336:
Traceback (most recent call last):
  File "/usr/lib/python3.9/threading.py", line 954, in _bootstrap_inner
    self.run()
  File "/usr/lib/python3.9/threading.py", line 1266, in run
    self.function(*self.args, **self.kwargs)
  File "/home/vboxuser/Git/imt4905/rtun-routing/lsr.py", line 662, in runDijkstra
    rp_node = rp_paths[prev_node][next_node]
KeyError: 'P1'
Exception in thread Thread-338:
Traceback (most recent call last):
  File "/usr/lib/python3.9/threading.py", line 954, in _bootstrap_inner
    self.run()
  File "/usr/lib/python3.9/threading.py", line 1266, in run
    self.function(*self.args, **self.kwargs)
  File "/home/vboxuser/Git/imt4905/rtun-routing/lsr.py", line 662, in runDijkstra
    rp_node = rp_paths[prev_node][next_node]
KeyError: 'P1'
Exception in thread Thread-343:
Traceback (most recent call last):
  File "/usr/lib/python3.9/threading.py", line 954, in _bootstrap_inner
    self.run()
  File "/usr/lib/python3.9/threading.py", line 1266, in run
    self.function(*self.args, **self.kwargs)
  File "/home/vboxuser/Git/imt4905/rtun-routing/lsr.py", line 662, in runDijkstra
    rp_node = rp_paths[prev_node][next_node]
KeyError: 'P1'
Exception in thread Thread-380:
Traceback (most recent call last):
  File "/usr/lib/python3.9/threading.py", line 954, in _bootstrap_inner
    self.run()
  File "/usr/lib/python3.9/threading.py", line 1266, in run
    self.function(*self.args, **self.kwargs)
  File "/home/vboxuser/Git/imt4905/rtun-routing/lsr.py", line 662, in runDijkstra
    rp_node = rp_paths[prev_node][next_node]
KeyError: 'P1'
Exception in thread Thread-430:
Traceback (most recent call last):
  File "/usr/lib/python3.9/threading.py", line 954, in _bootstrap_inner
    self.run()
  File "/usr/lib/python3.9/threading.py", line 1266, in run
    self.function(*self.args, **self.kwargs)
  File "/home/vboxuser/Git/imt4905/rtun-routing/lsr.py", line 662, in runDijkstra
    rp_node = rp_paths[prev_node][next_node]
KeyError: 'P1'
Exception in thread Thread-435:
Traceback (most recent call last):
  File "/usr/lib/python3.9/threading.py", line 954, in _bootstrap_inner
    self.run()
  File "/usr/lib/python3.9/threading.py", line 1266, in run
    self.function(*self.args, **self.kwargs)
  File "/home/vboxuser/Git/imt4905/rtun-routing/lsr.py", line 662, in runDijkstra
    rp_node = rp_paths[prev_node][next_node]
KeyError: 'P1'
Exception in thread Thread-442:
Traceback (most recent call last):
  File "/usr/lib/python3.9/threading.py", line 954, in _bootstrap_inner
    self.run()
  File "/usr/lib/python3.9/threading.py", line 1266, in run
    self.function(*self.args, **self.kwargs)
  File "/home/vboxuser/Git/imt4905/rtun-routing/lsr.py", line 662, in runDijkstra
    rp_node = rp_paths[prev_node][next_node]
KeyError: 'P1'
Exception in thread Thread-464:
Traceback (most recent call last):
  File "/usr/lib/python3.9/threading.py", line 954, in _bootstrap_inner
    self.run()
  File "/usr/lib/python3.9/threading.py", line 1266, in run
    self.function(*self.args, **self.kwargs)
  File "/home/vboxuser/Git/imt4905/rtun-routing/lsr.py", line 662, in runDijkstra
    rp_node = rp_paths[prev_node][next_node]
KeyError: 'P1'
Exception in thread Thread-475:
Traceback (most recent call last):
  File "/usr/lib/python3.9/threading.py", line 954, in _bootstrap_inner
    self.run()
  File "/usr/lib/python3.9/threading.py", line 1266, in run
    self.function(*self.args, **self.kwargs)
  File "/home/vboxuser/Git/imt4905/rtun-routing/lsr.py", line 662, in runDijkstra
    rp_node = rp_paths[prev_node][next_node]
KeyError: 'P1'
Exception in thread Thread-481:
Traceback (most recent call last):
  File "/usr/lib/python3.9/threading.py", line 954, in _bootstrap_inner
    self.run()
  File "/usr/lib/python3.9/threading.py", line 1266, in run
    self.function(*self.args, **self.kwargs)
  File "/home/vboxuser/Git/imt4905/rtun-routing/lsr.py", line 662, in runDijkstra
    rp_node = rp_paths[prev_node][next_node]
KeyError: 'P1'
Exception in thread Thread-487:
Traceback (most recent call last):
  File "/usr/lib/python3.9/threading.py", line 954, in _bootstrap_inner
    self.run()
  File "/usr/lib/python3.9/threading.py", line 1266, in run
    self.function(*self.args, **self.kwargs)
  File "/home/vboxuser/Git/imt4905/rtun-routing/lsr.py", line 662, in runDijkstra
    rp_node = rp_paths[prev_node][next_node]
KeyError: 'P1'
Exception in thread Thread-504:
Traceback (most recent call last):
  File "/usr/lib/python3.9/threading.py", line 954, in _bootstrap_inner
    self.run()
  File "/usr/lib/python3.9/threading.py", line 1266, in run
    self.function(*self.args, **self.kwargs)
  File "/home/vboxuser/Git/imt4905/rtun-routing/lsr.py", line 662, in runDijkstra
    rp_node = rp_paths[prev_node][next_node]
KeyError: 'P1'
Exception ignored in: <module 'threading' from '/usr/lib/python3.9/threading.py'>
Traceback (most recent call last):
  File "/usr/lib/python3.9/threading.py", line 1428, in _shutdown
    lock.acquire()
KeyboardInterrupt: 
